Workbook

Sheet Calculator
A1: Paste protocol into column A and enter number of chambers to calculate experiment volumes | D1: Green-shaded areas require user input for each experiment. No other area should be changed. Total volumes and Reagent Prep sheets are auto-calculated from chamber numbers
A2: Date: | B2: 2026XXXX | E2: Notes to Automation Set Up Tech:
A3: Experiment name: | B3: 2026XXXX_[Condition]_[Slide_Numbers]_[SampleName] | E3: Additional hyb cycles beyond hyb02 should follow same volume and oligo concentration as hyb01 and hyb 02. Thus, this calculator does not calculate for futher cycles. ***Hyb02 etc are called userdefined cycles in the "Reagent Sequence Files" folder. Double check that the sequences files are called corrrectly in the protocol.csv | I3: This top section marks out relatively how much of each solution is used in a given cycle
A4: Number of Chambers: | B4: 3 | J4: CRM | K4: Block | L4: IRM | M4: USM | N4: strip | O4: FISH wash | P4: bc primer mix | Q4: gene primer mix | R4: Hyb01 oligos mix | S4: Hyb02 oligo mix | T4: Sytox | U4: pbst | V4: inc. buffer
A5: Gene primers: | B5: ys220 | I5: bcseq r1 | K5: 1 | L5: 2 | M5: 1.5 | T5: 2 | U5: 26 | V5: 7.5
A6: BC primer: | B6: MR853 | I6: bcseq r2+ | J6: 2 | K6: 1 | L6: 2 | M6: 1.5 | T6: 2 | U6: 24 | V6: 14
A7: Hyb Primers: | B7: XCAI 154, xc2758, xc2759, xc2760 | E7: This section counts the number of times each cycle runs | I7: geneseq r1 | K7: 1 | L7: 1 | M7: 1.5 | T7: 2 | U7: 26 | V7: 4.5
A8: Additional Hyb primers: | B8: XCAI145, XC2759, XCAI150, XCAI 154 | I8: geneseq r2+ | J8: 1 | K8: 1 | L8: 1 | M8: 1.5 | T8: 2 | U8: 24 | V8: 8
A9: Protocol | E9: Number of sequences | I9: bc primer | O9: 10 | P9: 1 | U9: 2
A10: process | B10: Copy your protocol into this left column | E10: Fluidics_sequence_bcseq01 | F10: =COUNTIF(A:A, "Fluidics*bcseq01") -> 1 | I10: gene primer | O10: 10 | Q10: 1 | U10: 2
A11: Fluidics_sequence_add_gene_primer | B11: Always start with process | E11: Fluidics_sequence_bcseq02+ | F11: =COUNTIF(A:A, "Fluidics*bcseq*")-F10 -> 14 | I11: hyb | M11: 1.5 | O11: 10 | R11: 1 | T11: 4 | U11: 4
A12: Fluidics_sequence_geneseq01 | E12: Fluidics_sequence_geneseq01 | F12: =COUNTIF(A:A,"Fluidics*geneseq01*") -> 1 | I12: Strip | N12: 24
A13: imagecycle00 | B13: Always include the first focusing imagecycle00 prior | E13: Fluidics_sequence_geneseq02+ | F13: =COUNTIF(A:A,"Fluidics*geneseq*")-F12 -> 6 | I13: bc primer rehyb | O13: 8 | P13: 1
A14: imagecycle_geneseq01 | B14: to the actual first image cycle | E14: Fluidics_sequence_hyb01 | F14: =COUNTIF(A:A, "Fluidics*HYB*")-F15-F20 -> 0 | I14: gene primer rehyb | O14: 8 | Q14: 1 | U14: 3
A15: Fluidics_sequence_geneseq02 | E15: Fluidics_sequence_hyb01_rehyb | F15: =COUNTIF(A:A,"Fluidics*HYB_rehyb01") -> 1 | I15: hyb rehyb01 | M15: 1.5 | O15: 8 | R15: 1 | T15: 4 | U15: 4
A16: imagecycle_geneseq02 | E16: Fluidics_sequence_hyb02_rehyb | F16: =COUNTIF(A:A,"Fluidics*user_defined*") -> 1 | I16: hyb rehyb02 | M16: 1.5 | O16: 8 | S16: 1 | T16: 4 | U16: 4
A17: Fluidics_sequence_geneseq03 | B17: Images will be saved under the folder listed | E17: Fluidics_sequence_add_gene_primer01 | F17: =COUNTIF(A:A, "Fluidics_sequence_add_gene_primer*")-F18 -> 1
A18: imagecycle_geneseq03 | B18: in the imagecycle line (geneseq03) | E18: Fluidics_sequence_add_gene_primer01_rehyb | F18: =COUNTIF(A:A, "Fluidics_sequence_add_gene_primer_rehyb*") -> 0 | I18: This section calculates the total volume the different cycles will use for each reagent
A19: Fluidics_sequence_geneseq04 | E19: Fluidics_sequence_add_bc_primer01 | F19: =COUNTIF(A:A,"Fluidics_sequence_add_bc_primer*")-F20 -> 0 | I19: total volume
A20: imagecycle_geneseq04 | E20: Fluidics_sequence_add_bc_primer01_rehyb | F20: =COUNTIF(A:A, "Fluidics_sequence_add_bc_primer_rehyb*") -> 1 | I20: bcseq r1 | J20: =J5*$F28 -> 0 | K20: =K5*$F28 -> 3 | L20: =L5*$F28 -> 6 | M20: =M5*$F28 -> 4.5 | N20: =N5*$F28 -> 0 | O20: =O5*$F28 -> 0 | P20: =P5*$F28 -> 0 | Q20: =Q5*$F28 -> 0 | ... V20: =V5*$F28 -> 22.5
A21: Fluidics_sequence_geneseq05 | E21: Fluidics_sequence_strip | F21: =COUNTIF(A:A, "Fluidics_sequence_strip*") -> 3 | I21: bcseq r2+ | J21: =J6*$F29 -> 84 | K21: =K6*$F29 -> 42 | L21: =L6*$F29 -> 84 | M21: =M6*$F29 -> 63 | N21: =N6*$F29 -> 0 | O21: =O6*$F29 -> 0 | P21: =P6*$F29 -> 0 | Q21: =Q6*$F29 -> 0 | ... V21: =V6*$F29 -> 588
A22: imagecycle_geneseq05 | I22: geneseq r1 | J22: =J7*$F30 -> 0 | K22: =K7*$F30 -> 3 | L22: =L7*$F30 -> 3 | M22: =M7*$F30 -> 4.5 | N22: =N7*$F30 -> 0 | O22: =O7*$F30 -> 0 | P22: =P7*$F30 -> 0 | Q22: =Q7*$F30 -> 0 | ... V22: =V7*$F30 -> 13.5
A23: Fluidics_sequence_geneseq06 | I23: geneseqr2+ | J23: =J8*$F31 -> 18 | K23: =K8*$F31 -> 18 | L23: =L8*$F31 -> 18 | M23: =M8*$F31 -> 27 | N23: =N8*$F31 -> 0 | O23: =O8*$F31 -> 0 | P23: =P8*$F31 -> 0 | Q23: =Q8*$F31 -> 0 | ... V23: =V8*$F31 -> 144
A24: imagecycle_geneseq06 | I24: bc primer | J24: =J9*$F32 -> 0 | K24: =K9*$F32 -> 0 | L24: =L9*$F32 -> 0 | M24: =M9*$F32 -> 0 | N24: =N9*$F32 -> 0 | O24: =O9*$F32 -> 0 | P24: =P9*$F32 -> 0 | Q24: =Q9*$F32 -> 0 | ... V24: =V9*$F32 -> 0
A25: Fluidics_sequence_geneseq07 | I25: gene primer | J25: =J10*$F33 -> 0 | K25: =K10*$F33 -> 0 | L25: =L10*$F33 -> 0 | M25: =M10*$F33 -> 0 | N25: =N10*$F33 -> 0 | O25: =O10*$F33 -> 30 | P25: =P10*$F33 -> 0 | Q25: =Q10*$F33 -> 3 | ... V25: =V10*$F33 -> 0
A26: imagecycle_geneseq07 | I26: hyb | J26: =J11*$F34 -> 0 | K26: =K11*$F34 -> 0 | L26: =L11*$F34 -> 0 | M26: =M11*$F34 -> 0 | N26: =N11*$F34 -> 0 | O26: =O11*$F34 -> 0 | P26: =P11*$F34 -> 0 | Q26: =Q11*$F34 -> 0 | ... V26: =V11*$F34 -> 0
A27: Fluidics_sequence_strip01 | E27: Number of sequences * Number of chambers run | F27: Number of rounds | I27: Strip | J27: =J12*$F35 -> 0 | K27: =K12*$F35 -> 0 | L27: =L12*$F35 -> 0 | M27: =M12*$F35 -> 0 | N27: =N12*$F35 -> 216 | O27: =O12*$F35 -> 0 | P27: =P12*$F35 -> 0 | Q27: =Q12*$F35 -> 0 | ... V27: =V12*$F35 -> 0
A28: Fluidics_sequence_HYB_rehyb01 | E28: Fluidics_sequence_bcseq01 | F28: =F10*$B$4 -> 3 | I28: bc primer rehyb | J28: =J13*$F36 -> 0 | K28: =K13*$F36 -> 0 | L28: =L13*$F36 -> 0 | M28: =M13*$F36 -> 0 | N28: =N13*$F36 -> 0 | O28: =O13*$F36 -> 24 | P28: =P13*$F36 -> 3 | Q28: =Q13*$F36 -> 0 | ... V28: =V13*$F36 -> 0
A29: imagecycle_hyb01 | E29: Fluidics_sequence_bcseq02+ | F29: =F11*$B$4 -> 42 | I29: gene primer rehyb | J29: =J14*$F37 -> 0 | K29: =K14*$F37 -> 0 | L29: =L14*$F37 -> 0 | M29: =M14*$F37 -> 0 | N29: =N14*$F37 -> 0 | O29: =O14*$F37 -> 0 | P29: =P14*$F37 -> 0 | Q29: =Q14*$F37 -> 0 | ... V29: =V14*$F37 -> 0
A30: Fluidics_sequence_strip02 | E30: Fluidics_sequence_geneseq01 | F30: =F12*$B$4 -> 3 | I30: hyb rehyb | J30: =J15*$F38 -> 0 | K30: =K15*$F38 -> 0 | L30: =L15*$F38 -> 0 | M30: =M15*$F38 -> 4.5 | N30: =N15*$F38 -> 0 | O30: =O15*$F38 -> 24 | P30: =P15*$F38 -> 0 | Q30: =Q15*$F38 -> 0 | ... V30: =V15*$F38 -> 0
A31: Fluidics_sequence_add_bc_primer_rehyb01 | E31: Fluidics_sequence_geneseq02+ | F31: =F13*$B$4 -> 18 | I31: hyb rehyb02 | J31: =J16*$F39 -> 0 | K31: =K16*$F39 -> 0 | L31: =L16*$F39 -> 0 | M31: =M16*$F39 -> 4.5 | N31: =N16*$F39 -> 0 | O31: =O16*$F39 -> 24 | P31: =P16*$F39 -> 0 | Q31: =Q16*$F39 -> 0 | ... V31: =V16*$F39 -> 0
A32: Fluidics_sequence_bcseq01 | E32: bc primer | F32: =F18*B4 -> 0
A33: imagecycle_bcseq01 | E33: gene primer | F33: =F17*B4 -> 3
A34: Fluidics_sequence_bcseq02 | E34: hyb | F34: =F14*B4 -> 0 | I34: These are the calculations for total volumes necessary to complete the protocol. There is an additional buffer volume added to avoid running dry during the run
A35: imagecycle_bcseq02 | E35: Strip | F35: =F21*B4 -> 9 | J35: CRM | K35: Block | L35: IRM | M35: USM | N35: strip | O35: FISH wash | P35: bc primer mix | Q35: gene primer mix | R35: Hyb 01 oligos mix | S35: Hyb 02 oligos mix | T35: DAPI | U35: PBST | V35: inc. buffer
A36: Fluidics_sequence_bcseq03 | E36: bc primer rehyb | F36: =F20*B4 -> 3 | J36: =(ROUNDUP((SUM(J20:J31)*1.05),0))+(1*B4)+2 -> 113 | K36: =ROUNDUP((SUM(K20:K31)*1.05), 0)+(1*B4)+10 -> 83 | L36: =ROUNDUP((SUM(L20:L31)*1.05), 0)+(1*B4)+2 -> 122 | M36: =ROUNDUP((SUM(M20:M31)*1.05), 0)+(1*B4)+4 -> 121 | N36: =ROUNDUP((SUM(N20:N31)*1.05), 0)+15 -> 242 | O36: =ROUNDUP((SUM(O20:O31)*1.1), -1)+15 -> 135 | P36: =ROUNDUP((SUM(P20:P30)*1.05), 0)+(1*B4)+1 -> 8 | Q36: =ROUNDUP((SUM(Q20:Q30)*1.05), 0)+(1*B4)+1 -> 8 | R36: =ROUNDUP((SUM(R20:R30)*1.05), 0)+(1*B4)+1 -> 8 | S36: =ROUNDUP((SUM(S20:S31)*1.05), 0)+(1*$B$4)+1 -> 8 | T36: =ROUNDUP((SUM(T20:T31)*1.05), 0)+25 -> 189 | U36: =ROUNDUP((SUM(U20:U31)*1.1)+50, -2) -> 1900 | V36: =CEILING((SUM(V20:V31)*1.1+50)/500,1)*500 -> 1000
A37: imagecycle_bcseq03 | E37: gene primer rehyb | F37: =F18*B4 -> 0 | I37: Total volume | J37: =IF(J36=((1*$B$4)+1), 0,J36) -> 113 | K37: =IF(K36=((1*$B$4)+1), 0,K36) -> 83 | L37: =IF(L36=((1*$B$4)+1), 0,L36) -> 122 | M37: =IF(M36=((1*$B$4)+1), 0,M36) -> 121 | N37: =IF(N36=15, 0,N36) -> 242 | O37: =IF(O36=15, 0,O36) -> 135 | P37: =IF(P36=((1*$B$4)+1), 0,P36) -> 8 | Q37: =IF(Q36=((1*$B$4)+1), 0,Q36) -> 8 | R37: =IF(R36=((1*$B$4)+1), 0,R36) -> 8 | S37: =IF(S36=((1*$B$4)+1), 0,S36) -> 8 | T37: =IF(T36=15, 0,T36) -> 189 | U37: =IF(U36=((1*$B$4)+1), 0,U36) -> 1900 | V37: =IF(V36=((1*$B$4)+1), 0,V36) -> 1000
A38: Fluidics_sequence_bcseq04 | E38: hyb rehyb | F38: =F15*B4 -> 3
A39: imagecycle_bcseq04 | E39: hyb rehyb02 | F39: =F16*B4 -> 3
A40: Fluidics_sequence_bcseq05 | I40: Kits needed:
...

Sheet Reagent Prep
A2: Experiment: | B2: =Calculator!B3 -> 2026XXXX_[Condition]_[Slide_Numbers]_[SampleName] | G2: Total volumes:
A3: Imaging Date: | B3: =Calculator!B2 -> 2026XXXX | G3: CRM | H3: Block | I3: IRM | J3: USM | K3: strip | L3: FISH wash
A4: Reagent Prep | G4: =Calculator!J37 -> 113 | H4: =Calculator!K37 -> 83 | I4: =Calculator!L37 -> 122 | J4: =Calculator!M37 -> 121 | K4: =Calculator!N37 -> 242 | L4: =Calculator!O37 -> 135
A5: Step 1 | B5: Input protocol and number of chambers into calculator portion of this sheet | G5: bc primer mix | H5: gene primer mix | I5: hyb oligos mix | J5: DAPI | K5: PBST | L5: inc. buffer
A6: Step 2 | B6: Thaw reagents (check for extra reagent in Reagent Cave or Alder Freezer) | C6: # of kits | G6: =Calculator!P37 -> 8 | H6: =Calculator!Q37 -> 8 | I6: =Calculator!R37 -> 8 | J6: =Calculator!T37 -> 189 | K6: =Calculator!U37 -> 1900 | L6: =Calculator!V37 -> 1000
B7: IRM (IMS) (21mL per kit) | C7: =Calculator!J41 -> 6
B8: CRM (CMS) (21mL per kit) | C8: =Calculator!J42 -> 6
B9: USM (SRE) (30mL per kit) | C9: =Calculator!J43 -> 5
A10: Step 3 | B10: Label tubes with reagent name, volume, and date. Reagents and volumes can be found on the last page of this worksheet
A11: Step 4 | B11: Check volumes | C11: Volumes needed
B12: FISH wash | C12: =ROUNDUP((Calculator!O37+Calculator!P37+Calculator!Q37+Calculator!R37)*1.05,0)&" mL" -> 167 mL
B13: Strip | C13: =ROUNDUP((Calculator!N37)*1.05,0)&" mL" -> 255 mL
B14: 2% PBST | C14: =ROUNDUP((Calculator!K37+Calculator!U37+Calculator!T37)*1.05,-1)&" mL" -> 2290 mL
B15: Incorporation buffer | C15: =ROUNDUP((Calculator!V37)*1.1,-1)&" mL" -> 1100 mL
A16: Step 5 | B16: Make bulk reagents as needed | C16: Recipes | E16: *These are easy to reference recipes for the bulk reagents
B17: FISH wash (1000mL)
B18: Water | C18: 800 mL
B19: 20xSSC | C19: 100 mL
B20: Formamide | C20: 100 mL
B21: Tween-20 | C21: 1000 uL
B22: Strip (500mL)
B23: Water | C23: 150 mL
B24: 20xSSC | C24: 50 mL
B25: Formamide | C25: 300 mL
B26: Tween-20 | C26: 500 uL
B27: 2% PBST (1L)
B28: Water | C28: 880 mL
B29: 10xPBS | C29: 100 mL
B30: Tween-20 | C30: 20 mL
A31: Step 6 | B31: Filter reagents | C31: Minimum volumes needed
B32: PBST | C32: =C14 -> 2290 mL
B33: Incorporation buffer | C33: =C15 -> 1100 mL
B34: FISH wash | C34: =C12 -> 167 mL
B35: Strip | C35: =C13 -> 255 mL
B36: Put all bulk reagent tubes into fluidics system rack | E36: **Use the filtered PBST and FISH wash for the next section prior to hooking them up to fluidics system
A37: Step 7 | B37: Make Oligo Mixes and DAPI, use pre-filtered FISH wash and PBST. Add Therminator to IRM | C37: Recipes
B38: Hyb mix (1:400 each oligo)
B39: FISH wash (prefiltered) | C39: =Calculator!R37&" mL" -> 8 mL | E39: ***If there are additional Hyb cycles, they follow the same concentrations, but are not listed here.
B40: =Calculator!B7 -> XCAI 154, xc2758, xc2759, xc2760 | C40: =Calculator!R37/0.4&" uL each" -> 20 uL each
B41: BC mix (1:100)
...
